<?xml version='1.0'?>
<sdf version='1.6'>

  <model name='ship'>
    <pose>0 0 0 0 0 0</pose>
    <static>false</static>

    <plugin name="hydrodynamics" filename="libHydrodynamicsPlugin.so">
      <!-- Wave Model -->
      <wave_model>ocean_waves</wave_model>

      <!-- Hydrodynamics -->
      <damping_on>true</damping_on>
      <viscous_drag_on>true</viscous_drag_on>
      <pressure_drag_on>true</pressure_drag_on>

      <!-- Markers -->
      <markers>
        <update_rate>30</update_rate>
        <water_patch>false</water_patch>
        <waterline>false</waterline>
        <underwater_surface>false</underwater_surface>
      </markers>
    </plugin>

    <link name="base_link">
      <visual name="base_visual">
	<pose>0 0 0 1.6707 0 0</pose>
        <geometry>
          <mesh>
            <uri>model://ship/meshes/new_ship.dae</uri>
	    <scale>5 5 5</scale>
          </mesh>
        </geometry>
      </visual>
      <collision name="base_collision">
	<pose>0 0 1 0 0 0</pose>
        <geometry>
          <box>
            <size>10 4 2</size>
          </box>
        </geometry>
      </collision>

      <!-- Mass and inertial assume volume is 0.25 densitity of water -->
      <inertial>
        <pose>0 0 0 0 0 0</pose>
        <mass>30000</mass>
	<inertia>
          <ixx>33333</ixx>
          <ixy>0.0</ixy>
          <ixz>0.0</ixz>
          <iyy>173333</iyy>
          <iyz>0.0</iyz>
          <izz>193333</izz>
        </inertia>
      </inertial>
    </link>


<!--add imu-->
        <link name="imu_link">
          <pose>0 0 0 0 0 0</pose>
          <collision name="collision">
            <pose>0 0 0.3 0 0 0</pose>
            <geometry>
              <box>
                <size>0.1 0.1 0.1</size>
              </box>
            </geometry>
          </collision>
          <inertial>
            <mass>0.016</mass>
            <inertia>
               <ixx>0.0001</ixx>
               <ixy>0</ixy>
               <ixz>0</ixz>
               <iyy>0.0001</iyy>
               <iyz>0</iyz>
               <izz>0.0001</izz>
               <!-- low intertia necessary to avoid not disturb the ship -->
            </inertia>
          </inertial>

      <sensor name="imu_sensor" type="imu">
      <always_on>true</always_on>
      <update_rate>100</update_rate>
      <visualize>true</visualize>
      <topic>__default_topic__</topic>
      <plugin filename="libgazebo_ros_imu_sensor.so" name="imu_plugin">
        <topicName>imu</topicName>
        <bodyName>imu_link</bodyName>
        <updateRateHZ>10.0</updateRateHZ>
        <gaussianNoise>0.0</gaussianNoise>
        <xyzOffset>0 0 0</xyzOffset>
        <rpyOffset>0 0 0</rpyOffset>
        <frameName>imu_link</frameName>
        <initialOrientationAsReference>false</initialOrientationAsReference>
      </plugin>
      <pose>0 0 0 0 0 0</pose>
    </sensor>
    </link>

        <joint name="imu_joint" type="fixed">
          <pose>0 0 0 0 0 0</pose>
          <parent>base_link</parent>
          <child>imu_link</child>
        </joint>


<link name="world_link">
          <pose>0 0 0 0 0 0</pose>
          <collision name="collision">
            <pose>0 0 0 0 0 0</pose>
            <geometry>
              <box>
                <size>0.01 0.01 0.01</size>
              </box>
            </geometry>
          </collision>
          <inertial>
            <mass>0.006</mass>
            <inertia>
               <ixx>0.0001</ixx>
               <ixy>0</ixy>
               <ixz>0</ixz>
               <iyy>0.0001</iyy>
               <iyz>0</iyz>
               <izz>0.0001</izz>
               <!-- low intertia necessary to avoid not disturb the ship -->
            </inertia>
          </inertial>
</link>



<!--Can make the ship only move along Z axis-->
<joint name="world_joint" type="prismatic">
            <child>base_link</child>
            <parent>world</parent>
            <axis>
                <xyz>0 0 1</xyz>
            </axis>
        </joint>


<!-- GPS link -->
    <plugin name="gps_controller" filename="libhector_gazebo_ros_gps.so">
    <alwayson>true</alwayson>
    <updaterate>1.0</updaterate>
    <bodyname>base_link</bodyname>
    <topicname>/ship_gps</topicname>
    <velocitytopicname>/ship_velocity</velocitytopicname>
    <drift>5.0 5.0 5.0</drift>
    <gaussiannoise>0.1 0.1 0.1</gaussiannoise>
    <velocitydrift>0 0 0</velocitydrift>
    <velocitygaussiannoise>0.1 0.1 0.1</velocitygaussiannoise>
    <referenceLatitude>47.3977419</referenceLatitude>
    <referenceLongitude>8.5455939</referenceLongitude>
    <referenceAltitude>535.844915703</referenceAltitude>
</plugin>
  </model>
</sdf>
