<?xml version="1.0" ?>
<robot name="sdu_drone">


  <joint name="sdu_drone__/imu_joint" type="fixed">
    <parent link="sdu_drone_base_link"/>
    <child link="sdu_drone__/imu_link"/>
    <origin xyz="0 0 0" rpy="0 0 0"/>
    <axis xyz="1 0 0"/>
    <limit lower="0.0" upper="0.0" effort="0.0" velocity="0.0"/>
  </joint>
  <joint name="sdu_drone__rotor_0_joint" type="revolute">
    <parent link="sdu_drone_base_link"/>
    <child link="sdu_drone__rotor_0"/>
    <origin xyz="0   -0.37  0.17" rpy="0 0 0"/>
    <axis xyz="0 0 1"/>
    <limit lower="-1e+16" upper="1e+16" effort="0.0" velocity="0.0"/>
  </joint>

  <joint name="sdu_drone__rotor_1_joint" type="revolute">
    <parent link="sdu_drone_base_link"/>
    <child link="sdu_drone__rotor_1"/>
    <origin xyz="0   0.37 0.17" rpy="0 0 0"/>
    <axis xyz="0 0 1"/>
    <limit lower="-1e+16" upper="1e+16" effort="0.0" velocity="0.0"/>
  </joint>
  <joint name="sdu_drone__rotor_2_joint" type="revolute">
    <parent link="sdu_drone_base_link"/>
    <child link="sdu_drone__rotor_2"/>
    <origin xyz="0.32042 0.185   0.17" rpy="0 0 0"/>
    <axis xyz="0 0 1"/>
    <limit lower="-1e+16" upper="1e+16" effort="0.0" velocity="0.0"/>
  </joint>
  <joint name="sdu_drone__rotor_3_joint" type="revolute">
    <parent link="sdu_drone_base_link"/>
    <child link="sdu_drone__rotor_3"/>
    <origin xyz="-0.32042 -0.185    0.17" rpy="0 0 0"/>
    <axis xyz="0 0 1"/>
    <limit lower="-1e+16" upper="1e+16" effort="0.0" velocity="0.0"/>
  </joint>
  <joint name="sdu_drone__rotor_4_joint" type="revolute">
    <parent link="sdu_drone_base_link"/>
    <child link="sdu_drone__rotor_4"/>
    <origin xyz="0.32042 -0.185    0.17" rpy="0 0 0"/>
    <axis xyz="0 0 1"/>
    <limit lower="-1e+16" upper="1e+16" effort="0.0" velocity="0.0"/>
  </joint>
  <joint name="sdu_drone__rotor_5_joint" type="revolute">
    <parent link="sdu_drone_base_link"/>
    <child link="sdu_drone__rotor_5"/>
    <origin xyz="-0.32042  0.185    0.17" rpy="0 0 0"/>
    <axis xyz="0 0 1"/>
    <limit lower="-1e+16" upper="1e+16" effort="0.0" velocity="0.0"/>
  </joint>
  
  <link name="sdu_drone_base_link">
    <inertial>
      <mass value="1.5"/>
      <origin xyz="0 0 100" rpy="0 0 0"/>
      <inertia ixx="0.0762625" ixy="0" ixz="0" iyy="0.0762625" iyz="0" izz="0.1369"/>
    </inertial>
    <collision name="sdu_drone_base_link_inertia_collision">
      <origin xyz="0 0 0.1225" rpy="0 0 0"/>
      <geometry>
        <mesh filename="model://sdu_description/meshes/sdu_drone.dae" scale="1 1 1"/>
      </geometry>
    </collision>
    <visual name="sdu_drone_base_link_inertia_visual">
      <origin xyz="0 0 0.125" rpy="0 0 0"/>
      <geometry>
        <mesh filename="model://sdu_description/meshes/sdu_drone.dae" scale="1 1 1"/>
      </geometry>
    </visual>
  </link>

  <link name="sdu_drone__/imu_link">
    <inertial>
      <mass value="0.015"/>
      <origin xyz="0 0 0" rpy="0 0 0"/>
      <inertia ixx="1e-05" ixy="0" ixz="0" iyy="1e-05" iyz="0" izz="1e-05"/>
    </inertial>
  </link>
  <link name="sdu_drone__rotor_0">
    <inertial>
      <mass value="0.005"/>
      <origin xyz="0 0 0" rpy="0 0 0"/>
      <inertia ixx="9.75e-07" ixy="0" ixz="0" iyy="0.000273104" iyz="0" izz="0.000274004"/>
    </inertial>
    <collision name="sdu_drone__rotor_0_collision">
      <origin xyz="0 0 0" rpy="0 0 0"/>
      <geometry>
        <cylinder radius="0.128" length="0.005"/>
      </geometry>
    </collision>
    <visual name="sdu_drone__rotor_0_visual">
      <origin xyz="0 0 0" rpy="0 0 0"/>
      <geometry>
        <mesh filename="model://sdu_description/meshes/prop_cw.dae" scale="1.5 1.5 1.5"/>
      </geometry>
    </visual>
  </link>

  <link name="sdu_drone__rotor_1">
    <inertial>
      <mass value="0.005"/>
      <origin xyz="0 0 0" rpy="0 0 0"/>
      <inertia ixx="9.75e-07" ixy="0" ixz="0" iyy="0.000273104" iyz="0" izz="0.000274004"/>
    </inertial>
    <collision name="sdu_drone__rotor_1_collision">
      <origin xyz="0 0 0" rpy="0 0 0"/>
      <geometry>
        <cylinder radius="0.128" length="0.005"/>
      </geometry>
    </collision>
    <visual name="sdu_drone__rotor_1_visual">
      <origin xyz="0 0 0" rpy="0 0 0"/>
      <geometry>
        <mesh filename="model://sdu_description/meshes/prop_ccw.dae" scale="1.5 1.5 1.5"/>
      </geometry>
    </visual>
  </link>
  <link name="sdu_drone__rotor_2">
    <inertial>
      <mass value="0.005"/>
      <origin xyz="0 0 0" rpy="0 0 0"/>
      <inertia ixx="9.75e-07" ixy="0" ixz="0" iyy="0.000273104" iyz="0" izz="0.000274004"/>
    </inertial>
    <collision name="sdu_drone__rotor_2_collision">
      <origin xyz="0 0 0" rpy="0 0 0"/>
      <geometry>
        <cylinder radius="0.128" length="0.005"/>
      </geometry>
    </collision>
    <visual name="sdu_drone__rotor_2_visual">
      <origin xyz="0 0 0" rpy="0 0 0"/>
      <geometry>
        <mesh filename="model://sdu_description/meshes/prop_cw.dae" scale="1.5 1.5 1.5"/>
      </geometry>
    </visual>
  </link>
  <link name="sdu_drone__rotor_3">
    <inertial>
      <mass value="0.005"/>
      <origin xyz="0 0 0" rpy="0 0 0"/>
      <inertia ixx="9.75e-07" ixy="0" ixz="0" iyy="0.000273104" iyz="0" izz="0.000274004"/>
    </inertial>
    <collision name="sdu_drone__rotor_3_collision">
      <origin xyz="0 0 0" rpy="0 0 0"/>
      <geometry>
        <cylinder radius="0.128" length="0.005"/>
      </geometry>
    </collision>
    <visual name="sdu_drone__rotor_3_visual">
      <origin xyz="0 0 0" rpy="0 0 0"/>
      <geometry>
        <mesh filename="model://sdu_description/meshes/prop_ccw.dae" scale="1.5 1.5 1.5"/>
      </geometry>
    </visual>
  </link>
  <link name="sdu_drone__rotor_4">
    <inertial>
      <mass value="0.005"/>
      <origin xyz="0 0 0" rpy="0 0 0"/>
      <inertia ixx="9.75e-07" ixy="0" ixz="0" iyy="0.000273104" iyz="0" izz="0.000274004"/>
    </inertial>
    <collision name="sdu_drone__rotor_4_collision">
      <origin xyz="0 0 0" rpy="0 0 0"/>
      <geometry>
        <cylinder radius="0.128" length="0.005"/>
      </geometry>
    </collision>
    <visual name="sdu_drone__rotor_4_visual">
      <origin xyz="0 0 0" rpy="0 0 0"/>
      <geometry>
        <mesh filename="model://sdu_description/meshes/prop_ccw.dae" scale="1.5 1.5 1.5"/>
      </geometry>
    </visual>
  </link>
  <link name="sdu_drone__rotor_5">
    <inertial>
      <mass value="0.005"/>
      <origin xyz="0 0 0" rpy="0 0 0"/>
      <inertia ixx="9.75e-07" ixy="0" ixz="0" iyy="0.000273104" iyz="0" izz="0.000274004"/>
    </inertial>
    <collision name="sdu_drone__rotor_5_collision">
      <origin xyz="0 0 0" rpy="0 0 0"/>
      <geometry>
        <cylinder radius="0.128" length="0.005"/>
      </geometry>
    </collision>
    <visual name="sdu_drone__rotor_5_visual">
      <origin xyz="0 0 0" rpy="0 0 0"/>
      <geometry>
        <mesh filename="model://sdu_description/meshes/prop_cw.dae" scale="1.5 1.5 1.5"/>
      </geometry>
    </visual>
  </link>

  <gazebo>
  <plugin name='rosbag' filename='libgazebo_multirotor_base_plugin.so'>
      <robotNamespace/>
      <linkName>base_link</linkName>
      <rotorVelocitySlowdownSim>10</rotorVelocitySlowdownSim>
    </plugin>
   </gazebo>

	<gazebo>
	<plugin name='motor_model_0' filename='libgazebo_motor_model.so'>
	  <robotNamespace/>
	  <jointName>rotor_0_joint</jointName>
	  <linkName>rotor_0</linkName>
	  <turningDirection>cw</turningDirection>
	  <timeConstantUp>0.0125</timeConstantUp>
	  <timeConstantDown>0.025</timeConstantDown>
	  <maxRotVelocity>1100</maxRotVelocity>
	  <motorConstant>8.54858e-06</motorConstant>
	  <momentConstant>0.06</momentConstant>
	  <commandSubTopic>/gazebo/command/motor_speed</commandSubTopic>
	  <motorNumber>0</motorNumber>
	  <rotorDragCoefficient>0.000806428</rotorDragCoefficient>
	  <rollingMomentCoefficient>1e-06</rollingMomentCoefficient>
	  <motorSpeedPubTopic>/motor_speed/0</motorSpeedPubTopic>
	  <rotorVelocitySlowdownSim>10</rotorVelocitySlowdownSim>
	</plugin>
	</gazebo>

	<gazebo>
	<plugin name='motor_model_1' filename='libgazebo_motor_model.so'>
	  <robotNamespace/>
	  <jointName>rotor_1_joint</jointName>
	  <linkName>rotor_1</linkName>
	  <turningDirection>ccw</turningDirection>
	  <timeConstantUp>0.0125</timeConstantUp>
	  <timeConstantDown>0.025</timeConstantDown>
	  <maxRotVelocity>1100</maxRotVelocity>
	  <motorConstant>8.54858e-06</motorConstant>
	  <momentConstant>0.06</momentConstant>
	  <commandSubTopic>/gazebo/command/motor_speed</commandSubTopic>
	  <motorNumber>1</motorNumber>
	  <rotorDragCoefficient>0.000806428</rotorDragCoefficient>
	  <rollingMomentCoefficient>1e-06</rollingMomentCoefficient>
	  <motorSpeedPubTopic>/motor_speed/1</motorSpeedPubTopic>
	  <rotorVelocitySlowdownSim>10</rotorVelocitySlowdownSim>
	</plugin>
	</gazebo>

	<gazebo>
	<plugin name='motor_model_2' filename='libgazebo_motor_model.so'>
	  <robotNamespace/>
	  <jointName>rotor_2_joint</jointName>
	  <linkName>rotor_2</linkName>
	  <turningDirection>cw</turningDirection>
	  <timeConstantUp>0.0125</timeConstantUp>
	  <timeConstantDown>0.025</timeConstantDown>
	  <maxRotVelocity>1100</maxRotVelocity>
	  <motorConstant>8.54858e-06</motorConstant>
	  <momentConstant>0.06</momentConstant>
	  <commandSubTopic>/gazebo/command/motor_speed</commandSubTopic>
	  <motorNumber>2</motorNumber>
	  <rotorDragCoefficient>0.000806428</rotorDragCoefficient>
	  <rollingMomentCoefficient>1e-06</rollingMomentCoefficient>
	  <motorSpeedPubTopic>/motor_speed/2</motorSpeedPubTopic>
	  <rotorVelocitySlowdownSim>10</rotorVelocitySlowdownSim>
	</plugin>
	</gazebo>

	<gazebo>
	<plugin name='motor_model_3' filename='libgazebo_motor_model.so'>
	  <robotNamespace/>
	  <jointName>rotor_3_joint</jointName>
	  <linkName>rotor_3</linkName>
	  <turningDirection>ccw</turningDirection>
	  <timeConstantUp>0.0125</timeConstantUp>
	  <timeConstantDown>0.025</timeConstantDown>
	  <maxRotVelocity>1100</maxRotVelocity>
	  <motorConstant>8.54858e-06</motorConstant>
	  <momentConstant>0.06</momentConstant>
	  <commandSubTopic>/gazebo/command/motor_speed</commandSubTopic>
	  <motorNumber>3</motorNumber>
	  <rotorDragCoefficient>0.000806428</rotorDragCoefficient>
	  <rollingMomentCoefficient>1e-06</rollingMomentCoefficient>
	  <motorSpeedPubTopic>/motor_speed/3</motorSpeedPubTopic>
	  <rotorVelocitySlowdownSim>10</rotorVelocitySlowdownSim>
	</plugin>
	</gazebo>

	<gazebo>
	<plugin name='motor_model_4' filename='libgazebo_motor_model.so'>
	  <robotNamespace/>
	  <jointName>rotor_4_joint</jointName>
	  <linkName>rotor_4</linkName>
	  <turningDirection>ccw</turningDirection>
	  <timeConstantUp>0.0125</timeConstantUp>
	  <timeConstantDown>0.025</timeConstantDown>
	  <maxRotVelocity>1100</maxRotVelocity>
	  <motorConstant>8.54858e-06</motorConstant>
	  <momentConstant>0.06</momentConstant>
	  <commandSubTopic>/gazebo/command/motor_speed</commandSubTopic>
	  <motorNumber>4</motorNumber>
	  <rotorDragCoefficient>0.000806428</rotorDragCoefficient>
	  <rollingMomentCoefficient>1e-06</rollingMomentCoefficient>
	  <motorSpeedPubTopic>/motor_speed/3</motorSpeedPubTopic>
	  <rotorVelocitySlowdownSim>10</rotorVelocitySlowdownSim>
	</plugin>
	</gazebo>

	<gazebo>
	<plugin name='motor_model_5' filename='libgazebo_motor_model.so'>
	  <robotNamespace/>
	  <jointName>rotor_5_joint</jointName>
	  <linkName>rotor_5</linkName>
	  <turningDirection>cw</turningDirection>
	  <timeConstantUp>0.0125</timeConstantUp>
	  <timeConstantDown>0.025</timeConstantDown>
	  <maxRotVelocity>1100</maxRotVelocity>
	  <motorConstant>8.54858e-06</motorConstant>
	  <momentConstant>0.06</momentConstant>
	  <commandSubTopic>/gazebo/command/motor_speed</commandSubTopic>
	  <motorNumber>5</motorNumber>
	  <rotorDragCoefficient>0.000806428</rotorDragCoefficient>
	  <rollingMomentCoefficient>1e-06</rollingMomentCoefficient>
	  <motorSpeedPubTopic>/motor_speed/3</motorSpeedPubTopic>
	  <rotorVelocitySlowdownSim>10</rotorVelocitySlowdownSim>
	</plugin>
	</gazebo>

    <gazebo>
    <plugin name='groundtruth_plugin' filename='libgazebo_groundtruth_plugin.so'>
      <robotNamespace/>
    </plugin>
    </gazebo>    

    <gazebo>
    <plugin name='magnetometer_plugin' filename='libgazebo_magnetometer_plugin.so'>
      <robotNamespace/>
      <pubRate>20</pubRate>
      <noiseDensity>0.0004</noiseDensity>
      <randomWalk>6.4e-06</randomWalk>
      <biasCorrelationTime>600</biasCorrelationTime>
      <magTopic>/mag</magTopic>
    </plugin>
    </gazebo>

    <gazebo>
    <plugin name='barometer_plugin' filename='libgazebo_barometer_plugin.so'>
      <robotNamespace/>
      <pubRate>10</pubRate>
      <baroTopic>/baro</baroTopic>
    </plugin>
    </gazebo>

    <gazebo>
    <plugin name='parachute_plugin' filename='libgazebo_parachute_plugin.so'>
      <robotNamespace/>
      <commandSubTopic>/gazebo/command/motor_speed</commandSubTopic>
      <motorNumber>6</motorNumber>
    </plugin>
    </gazebo>

    <gazebo>
    <plugin name='mavlink_interface' filename='libgazebo_mavlink_interface.so'>
      <robotNamespace></robotNamespace>
      <imuSubTopic>/imu</imuSubTopic>
      <magSubTopic>/mag</magSubTopic>
      <baroSubTopic>/baro</baroSubTopic>
      <mavlink_addr>INADDR_ANY</mavlink_addr>
      <mavlink_udp_port>14560</mavlink_udp_port>
      <mavlink_tcp_port>4560</mavlink_tcp_port>
      <serialEnabled>false</serialEnabled>
      <serialDevice>/dev/ttyACM0</serialDevice>
      <baudRate>921600</baudRate>
      <qgc_addr>INADDR_ANY</qgc_addr>
      <qgc_udp_port>14550</qgc_udp_port>
      <sdk_addr>INADDR_ANY</sdk_addr>
      <sdk_udp_port>14540</sdk_udp_port>
      <hil_mode>0</hil_mode>
      <hil_state_level>0</hil_state_level>
      <vehicle_is_tailsitter>0</vehicle_is_tailsitter>
      <send_vision_estimation>1</send_vision_estimation>
      <send_odometry>0</send_odometry>
      <enable_lockstep>1</enable_lockstep>
      <use_tcp>1</use_tcp>
      <motorSpeedCommandPubTopic>/gazebo/command/motor_speed</motorSpeedCommandPubTopic>
      <control_channels>
        <channel name="rotor0">
          <input_index>0</input_index>
          <input_offset>0</input_offset>
          <input_scaling>1500</input_scaling>
          <zero_position_disarmed>0</zero_position_disarmed>
          <zero_position_armed>100</zero_position_armed>
          <joint_control_type>velocity</joint_control_type>
          <joint_name>rotor_0_joint</joint_name>
        </channel>
        <channel name="rotor1">
          <input_index>1</input_index>
          <input_offset>0</input_offset>
          <input_scaling>1500</input_scaling>
          <zero_position_disarmed>0</zero_position_disarmed>
          <zero_position_armed>100</zero_position_armed>
          <joint_control_type>velocity</joint_control_type>
          <joint_name>rotor_1_joint</joint_name>
        </channel>
        <channel name="rotor2">
          <input_index>2</input_index>
          <input_offset>0</input_offset>
          <input_scaling>1500</input_scaling>
          <zero_position_disarmed>0</zero_position_disarmed>
          <zero_position_armed>100</zero_position_armed>
          <joint_control_type>velocity</joint_control_type>
          <joint_name>rotor_2_joint</joint_name>
        </channel>
        <channel name="rotor3">
          <input_index>3</input_index>
          <input_offset>0</input_offset>
          <input_scaling>1500</input_scaling>
          <zero_position_disarmed>0</zero_position_disarmed>
          <zero_position_armed>100</zero_position_armed>
          <joint_control_type>velocity</joint_control_type>
          <joint_name>rotor_3_joint</joint_name>
        </channel>
        <channel name="rotor4">
          <input_index>4</input_index>
          <input_offset>0</input_offset>
          <input_scaling>1500</input_scaling>
          <zero_position_disarmed>0</zero_position_disarmed>
          <zero_position_armed>100</zero_position_armed>
          <joint_control_type>velocity</joint_control_type>
          <joint_name>rotor_4_joint</joint_name>
        </channel>
        <channel name="rotor5">
          <input_index>5</input_index>
          <input_offset>0</input_offset>
          <input_scaling>1500</input_scaling>
          <zero_position_disarmed>0</zero_position_disarmed>
          <zero_position_armed>100</zero_position_armed>
          <joint_control_type>velocity</joint_control_type>
          <joint_name>rotor_5_joint</joint_name>
        </channel>
      </control_channels>
    </plugin>
    </gazebo>

    <static>0</static>
    <gazebo>
    <plugin name='gazebo_imu_plugin' filename='libgazebo_imu_plugin.so'>
      <robotNamespace></robotNamespace>
      <linkName>/imu_link</linkName>
      <imuTopic>/imu</imuTopic>
      <gyroscopeNoiseDensity>0.0003394</gyroscopeNoiseDensity>
      <gyroscopeRandomWalk>3.8785e-05</gyroscopeRandomWalk>
      <gyroscopeBiasCorrelationTime>1000.0</gyroscopeBiasCorrelationTime>
      <gyroscopeTurnOnBiasSigma>0.0087</gyroscopeTurnOnBiasSigma>
      <accelerometerNoiseDensity>0.004</accelerometerNoiseDensity>
      <accelerometerRandomWalk>0.006</accelerometerRandomWalk>
      <accelerometerBiasCorrelationTime>300.0</accelerometerBiasCorrelationTime>
      <accelerometerTurnOnBiasSigma>0.196</accelerometerTurnOnBiasSigma>
    </plugin>
    </gazebo>
</robot>

